Workbook

Sheet Initial_magnetization_curve
A1: S356
A2: Plate 1
A3: MPE | J3: MPM | V3: AVERAGE
A4: 1A-Top | D4: 1B-Middle | G4: 1C-Bottom | J4: 4A-Top | M4: 4B-Middle | P4: 4C-Bottom | V4: H (A/m) | W4: B(T) | X4: μr (-)
A5: H (A/m) | B5: B(T) | C5: μr (-) | D5: H (A/m) | E5: B(T) | F5: μr (-) | G5: H (A/m) | H5: B(T) | I5: μr (-) | J5: H (A/m) | K5: B(T) | L5: μr (-) | M5: H (A/m) | N5: B(T) | O5: μr (-) | P5: H (A/m) | Q5: B(T) | R5: μr (-) | V5: =AVERAGE(A6,D6,G6,J6,M6,P6,D47,M47,D88,M88) | W5: =AVERAGE(B6,E6,H6,K6,N6,Q6,E47,N47,E88,N88) | X5: =AVERAGE(C6,F6,I6,L6,O6,R6,F47,O47,F88,O88)
A6: 4.12507 | B6: 0.00125756 | C6: 242.598 | D6: 4.12194 | E6: 0.00130912 | F6: 252.736 | G6: 4.1232 | H6: 0.00135685 | I6: 261.87 | J6: 4.12182 | K6: 0.00125439 | L6: 242.177 | M6: 4.11624 | N6: 0.00140593 | O6: 271.803 | P6: 4.13065 | Q6: 0.0012735 | R6: 245.341 | V6: =AVERAGE(A7,D7,G7,J7,M7,P7,D48,M48,D89,M89) | W6: =AVERAGE(B7,E7,H7,K7,N7,Q7,E48,N48,E89,N89) | X6: =AVERAGE(C7,F7,I7,L7,O7,R7,F48,O48,F89,O89)
A7: 8.31432 | B7: 0.00279035 | C7: 267.068 | D7: 8.32709 | E7: 0.00277937 | F7: 265.609 | G7: 8.31509 | H7: 0.00304446 | I7: 291.362 | J7: 8.31574 | K7: 0.00268223 | L7: 256.676 | M7: 8.32577 | N7: 0.00307004 | O7: 293.434 | P7: 8.31967 | Q7: 0.00276988 | R7: 264.938 | V7: =AVERAGE(A8,D8,G8,J8,M8,P8,D49,M49,D90,M90) | W7: =AVERAGE(B8,E8,H8,K8,N8,Q8,E49,N49,E90,N90) | X7: =AVERAGE(C8,F8,I8,L8,O8,R8,F49,O49,F90,O90)
A8: 13.0609 | B8: 0.00471187 | C8: 287.084 | D8: 13.0593 | E8: 0.00477391 | F8: 290.901 | G8: 13.0545 | H8: 0.00512315 | I8: 312.297 | J8: 13.0619 | K8: 0.00456161 | L8: 277.908 | M8: 13.0546 | N8: 0.0051943 | O8: 316.631 | P8: 13.0681 | Q8: 0.00470627 | R8: 286.585 | V8: =AVERAGE(A9,D9,G9,J9,M9,P9,D50,M50,D91,M91) | W8: =AVERAGE(B9,E9,H9,K9,N9,Q9,E50,N50,E91,N91) | X8: =AVERAGE(C9,F9,I9,L9,O9,R9,F50,O50,F91,O91)
A9: 17.257 | B9: 0.00653851 | C9: 301.512 | D9: 17.2646 | E9: 0.00655259 | F9: 302.027 | G9: 17.2491 | H9: 0.00705499 | I9: 325.477 | J9: 17.2578 | K9: 0.00631343 | L9: 291.118 | M9: 17.2604 | N9: 0.0072423 | O9: 333.899 | P9: 17.2532 | Q9: 0.00659264 | R9: 304.075 | V9: =AVERAGE(A10,D10,G10,J10,M10,P10,D51,M51,D92,M92) | W9: =AVERAGE(B10,E10,H10,K10,N10,Q10,E51,N51,E92,N92) | X9: =AVERAGE(C10,F10,I10,L10,O10,R10,F51,O51,F92,O92)
A10: 25.5965 | B10: 0.0106333 | C10: 330.582 | D10: 25.5993 | E10: 0.0106189 | F10: 330.097 | G10: 25.588 | H10: 0.0114254 | I10: 355.325 | J10: 25.6059 | K10: 0.0103341 | L10: 321.161 | M10: 25.6023 | N10: 0.0116571 | O10: 362.327 | P10: 25.5971 | Q10: 0.0105765 | R10: 328.806 | V10: =AVERAGE(A11,D11,G11,J11,M11,P11,D52,M52,D93,M93) | W10: =AVERAGE(B11,E11,H11,K11,N11,Q11,E52,N52,E93,N93) | X10: =AVERAGE(C11,F11,I11,L11,O11,R11,F52,O52,F93,O93)
A11: 33.9951 | B11: 0.0153381 | C11: 359.043 | D11: 33.984 | E11: 0.015159 | F11: 354.965 | G11: 33.9821 | H11: 0.0163544 | I11: 382.979 | J11: 33.9927 | K11: 0.0148452 | L11: 347.528 | M11: 33.9863 | N11: 0.0166769 | O11: 390.482 | P11: 34.0093 | Q11: 0.0152428 | R11: 356.661 | V11: =AVERAGE(A12,D12,G12,J12,M12,P12,D53,M53,D94,M94) | W11: =AVERAGE(B12,E12,H12,K12,N12,Q12,E53,N53,E94,N94) | X11: =AVERAGE(C12,F12,I12,L12,O12,R12,F53,O53,F94,O94)
A12: 39.2443 | B12: 0.0184847 | C12: 374.823 | D12: 39.227 | E12: 0.0181822 | F12: 368.852 | G12: 39.2337 | H12: 0.0196595 | I12: 398.751 | J12: 39.2373 | K12: 0.0179249 | L12: 363.535 | M12: 39.2465 | N12: 0.0200868 | O12: 407.286 | P12: 39.2453 | Q12: 0.0183488 | R12: 372.057 | V12: =AVERAGE(A13,D13,G13,J13,M13,P13,D54,M54,D95,M95) | W12: =AVERAGE(B13,E13,H13,K13,N13,Q13,E54,N54,E95,N95) | X12: =AVERAGE(C13,F13,I13,L13,O13,R13,F54,O54,F95,O95)
A13: 44.4924 | B13: 0.0219402 | C13: 392.415 | D13: 44.4781 | E13: 0.0213989 | F13: 382.855 | G13: 44.477 | H13: 0.0232053 | I13: 415.186 | J13: 44.4791 | K13: 0.0211718 | L13: 378.784 | M13: 44.4797 | N13: 0.023611 | O13: 422.418 | P13: 44.4812 | Q13: 0.0216366 | R13: 387.082 | V13: =AVERAGE(A14,D14,G14,J14,M14,P14,D55,M55,D96,M96) | W13: =AVERAGE(B14,E14,H14,K14,N14,Q14,E55,N55,E96,N96) | X13: =AVERAGE(C14,F14,I14,L14,O14,R14,F55,O55,F96,O96)
A14: 52.3402 | B14: 0.0274736 | C14: 417.706 | D14: 52.3218 | E14: 0.0265892 | F14: 404.402 | G14: 52.3195 | H14: 0.0287654 | I14: 437.519 | J14: 52.3309 | K14: 0.026398 | L14: 401.424 | M14: 52.3312 | N14: 0.0294033 | O14: 447.122 | P14: 52.3353 | Q14: 0.0269225 | R14: 409.364 | V14: =AVERAGE(A15,D15,G15,J15,M15,P15,D56,M56,D97,M97) | W14: =AVERAGE(B15,E15,H15,K15,N15,Q15,E56,N56,E97,N97) | X14: =AVERAGE(C15,F15,I15,L15,O15,R15,F56,O56,F97,O97)
A15: 61.2343 | B15: 0.0342616 | C15: 445.249 | D15: 61.2199 | E15: 0.033014 | F15: 429.137 | G15: 61.2125 | H15: 0.0358084 | I15: 465.517 | J15: 61.2098 | K15: 0.0329959 | L15: 428.972 | M15: 61.2178 | N15: 0.036557 | O15: 475.207 | P15: 61.22 | Q15: 0.0335437 | R15: 436.021 | V15: =AVERAGE(A16,D16,G16,J16,M16,P16,D57,M57,D98,M98) | W15: =AVERAGE(B16,E16,H16,K16,N16,Q16,E57,N57,E98,N98) | X15: =AVERAGE(C16,F16,I16,L16,O16,R16,F57,O57,F98,O98)
A16: 73.3235 | B16: 0.0446234 | C16: 484.295 | D16: 73.3074 | E16: 0.0426405 | F16: 462.876 | G16: 73.2944 | H16: 0.046524 | I16: 505.121 | J16: 73.3069 | K16: 0.0428678 | L16: 465.347 | M16: 73.3119 | N16: 0.0474823 | O16: 515.404 | P16: 73.3173 | Q16: 0.0435986 | R16: 473.213 | V16: =AVERAGE(A17,D17,G17,J17,M17,P17,D58,M58,D99,M99) | W16: =AVERAGE(B17,E17,H17,K17,N17,Q17,E58,N58,E99,N99) | X16: =AVERAGE(C17,F17,I17,L17,O17,R17,F58,O58,F99,O99)
A17: 81.6615 | B17: 0.0525422 | C17: 512.013 | D17: 81.6414 | E17: 0.049958 | F17: 486.95 | G17: 81.6302 | H17: 0.0546529 | I17: 532.785 | J17: 81.6499 | K17: 0.0504129 | L17: 491.333 | M17: 81.6432 | N17: 0.055863 | O17: 544.495 | P17: 81.6615 | Q17: 0.0511537 | R17: 498.483 | V17: =AVERAGE(A18,D18,G18,J18,M18,P18,D59,M59,D100,M100) | W17: =AVERAGE(B18,E18,H18,K18,N18,Q18,E59,N59,E100,N100) | X17: =AVERAGE(C18,F18,I18,L18,O18,R18,F59,O59,F100,O100)
... A40: 15794.9 | B40: 1.92613 | C40: 97.042 | D40: 15791.2 | E40: 1.90292 | F40: 95.895 | G40: 15788.8 | H40: 1.91277 | I40: 96.4055 | J40: 15792.2 | K40: 1.91516 | L40: 96.5058 | M40: 15792 | N40: 1.91664 | O40: 96.5815 | P40: 15793.1 | Q40: 1.91095 | R40: 96.2877 | V40: =AVERAGE(A41,D41,G41,J41,M41,P41,D82,M82,D123,M123) | W40: =AVERAGE(B41,E41,H41,K41,N41,Q41,E82,N82,E123,N123) | X40: =AVERAGE(C41,F41,I41,L41,O41,R41,F82,O82,F123,O123)
A41: 20714.1 | B41: 1.98925 | C41: 76.4212 | D41: 20709.5 | E41: 1.96615 | F41: 75.5503 | G41: 20706 | H41: 1.97649 | I41: 75.9607 | J41: 20710.5 | K41: 1.97859 | L41: 76.025 | M41: 20710.4 | N41: 1.97953 | O41: 76.0612 | P41: 20711.4 | Q41: 1.97456 | R41: 75.8667
A43: Plate 2
A44: MPE | J44: MPM
A45: 5A-Top | D45: 5B-Middle | G45: 5C-Bottom | J45: 8A-Top | M45: 8B-Middle | P45: 8C-Bottom
A46: H (A/m) | B46: B(T) | C46: μr (-) | D46: H (A/m) | E46: B(T) | F46: μr (-) | G46: H (A/m) | H46: B(T) | I46: μr (-) | J46: H (A/m) | K46: B(T) | L46: μr (-) | M46: H (A/m) | N46: B(T) | O46: μr (-) | P46: H (A/m) | Q46: B(T) | R46: μr (-)
A47: Not cut | D47: 4.12551 | E47: 0.00187574 | F47: 361.814 | G47: Not cut | J47: Not cut | M47: 4.10685 | N47: 0.00191394 | O47: 370.86 | P47: Not cut
D48: 8.31414 | E48: 0.00402417 | F48: 385.167 | M48: 8.32806 | N48: 0.0042323 | O48: 404.411
D49: 13.066 | E49: 0.00673297 | F49: 410.068 | M49: 13.0697 | N49: 0.00705903 | O49: 429.804
D50: 17.2599 | E50: 0.00927805 | F50: 427.769 | M50: 17.2614 | N50: 0.00982177 | O50: 452.797
D51: 25.5999 | E51: 0.0148457 | F51: 461.48 | M51: 25.5965 | N51: 0.0156694 | O51: 487.149
D52: 33.9922 | E52: 0.0209011 | F52: 489.305 | M52: 33.9865 | N52: 0.0220957 | O52: 517.357
D53: 39.2421 | E53: 0.0249716 | F53: 506.39 | M53: 39.2381 | N53: 0.0264682 | O53: 536.792
D54: 44.4798 | E54: 0.0292748 | F54: 523.747 | M54: 44.4775 | N54: 0.031097 | O54: 556.376
D55: 52.3276 | E55: 0.0362793 | F55: 551.72 | M55: 52.3331 | N55: 0.0386241 | O55: 587.316
D56: 61.2101 | E56: 0.0450956 | F56: 586.275 | M56: 61.2217 | N56: 0.0481508 | O56: 625.876
D57: 73.3011 | E57: 0.0588499 | F57: 638.889 | M57: 73.3059 | N57: 0.0631036 | O57: 685.023
D58: 81.6416 | E58: 0.0695781 | F58: 678.19 | M58: 81.6473 | N58: 0.0749386 | O58: 730.388
D59: 94.7455 | E59: 0.0899214 | F59: 755.257 | M59: 94.7338 | N59: 0.0976626 | O59: 820.377
... D82: 20709.3 | E82: 1.97773 | F82: 75.9964 | M82: 20709.7 | N82: 1.97859 | O82: 76.0276
A84: Plate 3
A85: MPE | J85: MPM
A86: 9A-Top | D86: 9B-Middle | G86: 9C-Bottom | J86: 12A-Top | M86: 12B-Middle | P86: 12C-Bottom
...

Sheet Major_hysteresis_loop
A1: S356
A2: Plate 1 | M2: Plate 2 | Y2: Plate 3
A3: MPE | G3: MPM | M3: MPE | S3: MPM | Y3: MPE | AE3: MPM
A4: 1A - Top | C4: 1B - Center | E4: 1C - Bottom | G4: 4A - Top | I4: 4B - Center | K4: 4C - Bottom | M4: 5A - Top | O4: 5B - Center | Q4: 5C - Bottom | S4: 8A - Top | U4: 8B - Center | W4: 8C - Bottom | Y4: 9A - Top | AA4: 9B - Center | AC4: 9C - Bottom | AE4: 12A - Top | AG4: 12B - Center | AI4: 12C - Bottom
A5: H (A/m) | B5: B(T) | C5: H (A/m) | D5: B(T) | E5: H (A/m) | F5: B(T) | G5: H (A/m) | H5: B(T) | I5: H (A/m) | J5: B(T) | K5: H (A/m) | L5: B(T) | M5: H (A/m) | N5: B(T) | O5: H (A/m) | P5: B(T) | Q5: H (A/m) | R5: B(T) | S5: H (A/m) | T5: B(T) | U5: H (A/m) | V5: B(T) | W5: H (A/m) | X5: B(T) | Y5: H (A/m) | Z5: B(T) | AA5: H (A/m) | AB5: B(T) | AC5: H (A/m) | AD5: B(T) | AE5: H (A/m) | AF5: B(T) | AG5: H (A/m) | AH5: B(T) | AI5: H (A/m) | AJ5: B(T)
A6: 19335.7 | B6: 1.968785 | C6: 19330.8 | D6: 1.94568 | E6: 19328 | F6: 1.9558575 | G6: 19331.7 | H6: 1.9577625 | I6: 19331.5 | J6: 1.9598 | K6: 19334.8 | L6: 1.9541425 | M6: Not cut | O6: 19331.4 | P6: 1.95817 | Q6: Not cut | S6: Not cut | U6: 19332.3 | V6: 1.958155 | W6: Not cut | Y6: Not cut | AA6: 19335.3 | AB6: 1.9527075 | AC6: Not cut | AE6: Not cut | AG6: 19347.9 | AH6: 1.95755 | AI6: Not cut
A7: 16217.6 | B7: 1.928735 | C7: 16213 | D7: 1.90613 | E7: 16210.8 | F7: 1.9159275 | G7: 16214.2 | H7: 1.9181525 | I7: 16214 | J7: 1.91989 | K7: 16216.4 | L7: 1.9145125 | O7: 16213.7 | P7: 1.918 | U7: 16214.6 | V7: 1.917895 | AA7: 16216.8 | AB7: 1.9125375 | AG7: 16227.8 | AH7: 1.91719
A8: 14346.1 | B8: 1.901735 | C8: 14342.4 | D8: 1.8794 | E8: 14340.6 | F8: 1.8888275 | G8: 14343.3 | H8: 1.8912625 | I8: 14343.4 | J8: 1.8929 | K8: 14345.4 | L8: 1.8876525 | O8: 14342.8 | P8: 1.89069 | U8: 14343.8 | V8: 1.890605 | AA8: 14345.6 | AB8: 1.8852775 | AG8: 14354.9 | AH8: 1.88999
A9: 12256.4 | B9: 1.868285 | C9: 12253.3 | D9: 1.84622 | E9: 12251.6 | F9: 1.8552675 | G9: 12254.1 | H9: 1.8579225 | I9: 12254.1 | J9: 1.85951 | K9: 12255.5 | L9: 1.8542525 | O9: 12253.5 | P9: 1.85718 | U9: 12254.3 | V9: 1.857135 | AA9: 12255.8 | AB9: 1.8515575 | AG9: 12263.7 | AH9: 1.85639
A10: 12011.3 | B10: 1.864125 | C10: 12008.1 | D10: 1.84209 | E10: 12006.5 | F10: 1.8510975 | G10: 12008.6 | H10: 1.8537425 | I10: 12009.2 | J10: 1.85536 | K10: 12010.1 | L10: 1.8501225 | O10: 12008.3 | P10: 1.85301 | U10: 12009 | V10: 1.852955 | AA10: 12010.7 | AB10: 1.8473375 | AG10: 12018.4 | AH10: 1.85214
A11: 11766.2 | B11: 1.859925 | C11: 11763 | D11: 1.83785 | E11: 11761.3 | F11: 1.8467975 | G11: 11763.5 | H11: 1.8495825 | I11: 11764 | J11: 1.85112 | K11: 11765 | L11: 1.8458625 | O11: 11763.6 | P11: 1.84867 | U11: 11763.8 | V11: 1.848735 | AA11: 11765.7 | AB11: 1.8430975 | AG11: 11773.3 | AH11: 1.84789
A12: 11521.1 | B12: 1.855645 | C12: 11517.7 | D12: 1.8337 | E12: 11516.2 | F12: 1.8423475 | G12: 11518.4 | H12: 1.8453625 | I12: 11518.9 | J12: 1.84667 | K12: 11520 | L12: 1.8415225 | O12: 11518.6 | P12: 1.8444 | U12: 11518.7 | V12: 1.844435 | AA12: 11520.5 | AB12: 1.8387675 | AG12: 11528.2 | AH12: 1.8436
A13: 11276 | B13: 1.851265 | C13: 11272.7 | D13: 1.82933 | E13: 11271.1 | F13: 1.8379975 | G13: 11273.4 | H13: 1.8410925 | I13: 11273.6 | J13: 1.84248 | K13: 11274.9 | L13: 1.8371325 | O13: 11273.4 | P13: 1.84008 | U13: 11273.5 | V13: 1.840155 | AA13: 11275.2 | AB13: 1.8343575 | AG13: 11282.6 | AH13: 1.83907
A14: 11030.9 | B14: 1.846845 | C14: 11027.6 | D14: 1.82491 | E14: 11026.2 | F14: 1.8335575 | G14: 11028.3 | H14: 1.8367025 | I14: 11028.5 | J14: 1.83813 | K14: 11029.8 | L14: 1.8327725 | O14: 11028.1 | P14: 1.83572 | U14: 11028.5 | V14: 1.835715 | AA14: 11029.9 | AB14: 1.8300075 | AG14: 11037.7 | AH14: 1.83448
A15: 10785.8 | B15: 1.842525 | C15: 10782.5 | D15: 1.82042 | E15: 10781.1 | F15: 1.8291075 | G15: 10783.6 | H15: 1.8322325 | I15: 10783.5 | J15: 1.83365 | K15: 10784.5 | L15: 1.8282425 | O15: 10783.1 | P15: 1.83117 | U15: 10783.6 | V15: 1.831255 | AA15: 10785 | AB15: 1.8255375 | AG15: 10792.3 | AH15: 1.82988
A16: 10540.5 | B16: 1.838005 | C16: 10537.6 | D16: 1.81591 | E16: 10536.1 | F16: 1.8245375 | G16: 10538.3 | H16: 1.8277225 | I16: 10538.4 | J16: 1.82914 | K16: 10539.4 | L16: 1.8236325 | O16: 10538.1 | P16: 1.82657 | U16: 10538.4 | V16: 1.826625 | AA16: 10540 | AB16: 1.8208375 | AG16: 10547.2 | AH16: 1.82523
A17: 10295.5 | B17: 1.833305 | C17: 10292.4 | D17: 1.81148 | E17: 10291 | F17: 1.8199275 | G17: 10293.1 | H17: 1.8232325 | I17: 10293.2 | J17: 1.82465 | K17: 10294.5 | L17: 1.8190725 | O17: 10292.9 | P17: 1.82203 | U17: 10293.1 | V17: 1.822055 | AA17: 10294.8 | AB17: 1.8161375 | AG17: 10301.9 | AH17: 1.8205
A18: 10050.2 | B18: 1.828615 | C18: 10047.4 | D18: 1.80682 | E18: 10045.6 | F18: 1.8152575 | G18: 10047.9 | H18: 1.8186625 | I18: 10048.2 | J18: 1.81998 | K18: 10049.5 | L18: 1.8143725 | O18: 10047.9 | P18: 1.81734 | U18: 10048 | V18: 1.817455 | AA18: 10049.5 | AB18: 1.8114975 | AG18: 10056.4 | AH18: 1.81569
... A242: 19340.1 | B242: 1.968905 | C242: 19333.3 | D242: 1.94492 | E242: 19331.2 | F242: 1.9548875 | G242: 19335.9 | H242: 1.9572325 | I242: 19334 | J242: 1.95794 | K242: 19337.5 | L242: 1.9533725 | O242: 19335.5 | P242: 1.95687 | U242: 19334.5 | V242: 1.957635 | AA242: 19337.9 | AB242: 1.9535175 | AG242: 19351 | AH242: 1.95803
A244: Max measured | M244: Max measured | Y244: Max measured
B245: 1A | C245: 1B | D245: 1C | E245: 4A | F245: 4B | G245: 4C | N245: 5A | O245: 5B | P245: 5C | Q245: 8A | R245: 8B | S245: 8C | Z245: 9A | AA245: 9B | AB245: 9C | AC245: 12A | AD245: 12B | AE245: 12C
A246: Hc (A/m) | B246: =0.5*_xlfn.FORECAST.LINEAR(0,A189:A190,B189:B190)-0.5*_xlfn.FORECAST.LINEAR(0,A71:A72,B71:B72) | C246: =0.5*_xlfn.FORECAST.LINEAR(0,C189:C190,D189:D190)-0.5*_xlfn.FORECAST.LINEAR(0,C71:C72,D71:D72) | D246: =0.5*_xlfn.FORECAST.LINEAR(0,E189:E190,F189:F190)-0.5*_xlfn.FORECAST.LINEAR(0,E71:E72,F71:F72) | E246: =0.5*_xlfn.FORECAST.LINEAR(0,G189:G190,H189:H190)-0.5*_xlfn.FORECAST.LINEAR(0,G71:G72,H71:H72) | F246: =0.5*_xlfn.FORECAST.LINEAR(0,I189:I190,J189:J190)-0.5*_xlfn.FORECAST.LINEAR(0,I71:I72,J71:J72) | G246: =0.5*_xlfn.FORECAST.LINEAR(0,K189:K190,L189:L190)-0.5*_xlfn.FORECAST.LINEAR(0,K71:K72,L71:L72) | M246: Hc (A/m) | O246: =0.5*_xlfn.FORECAST.LINEAR(0,O189:O190,P189:P190)-0.5*_xlfn.FORECAST.LINEAR(0,O71:O72,P71:P72) | R246: =0.5*_xlfn.FORECAST.LINEAR(0,U189:U190,V189:V190)-0.5*_xlfn.FORECAST.LINEAR(0,U71:U72,V71:V72) | Y246: Hc (A/m) | AA246: =0.5*_xlfn.FORECAST.LINEAR(0,AA189:AA190,AB189:AB190)-0.5*_xlfn.FORECAST.LINEAR(0,AA71:AA72,AB71:AB72) | AD246: =0.5*_xlfn.FORECAST.LINEAR(0,AG189:AG190,AH189:AH190)-0.5*_xlfn.FORECAST.LINEAR(0,AG71:AG72,AH71:AH72)
A247: Br (T) | B247: =B65*0.5-B183*0.5 | C247: =D65*0.5-D183*0.5 | D247: =F65*0.5-F183*0.5 | E247: =H65*0.5-H183*0.5 | F247: =J65*0.5-J183*0.5 | G247: =L65*0.5-L183*0.5 | M247: Br (T) | O247: =P65*0.5-P183*0.5 | R247: =V65*0.5-V183*0.5 | Y247: Br (T) | AA247: =AB65*0.5-AB183*0.5 | AD247: =AH65*0.5-AH183*0.5

Sheet Statistics
A1: Cross-section dispersion | D1: In-plate dispersion Plate 1 | F1: In-plate dispersion Plate 2 | H1: In-plate dispersion Plate 3 | J1: Plate-to-plate uniformity
A2: H (A/m) | B2: Plate 1 - MPE | C2: Plate 1 - MPM | D2: H (A/m) | E2: Std (%) | F2: H (A/m) | G2: Std (%) | H2: H (A/m) | I2: Std (%) | J2: H (A/m) | K2: Semi-diff (%)
A3: =AVERAGE(Initial_magnetization_curve!A6,Initial_magnetization_curve!D6,Initial_magnetization_curve!G6,Initial_magnetization_curve!J6,Initial_magnetization_curve!M6,Initial_magnetization_curve!P6) | B3: =STDEV(Initial_magnetization_curve!B6,Initial_magnetization_curve!E6,Initial_magnetization_curve!H6)/AVERAGE(Initial_magnetization_curve!B6,Initial_magnetization_curve!E6,Initial_magnetization_curve!H6)*100 | C3: =STDEV(Initial_magnetization_curve!K6,Initial_magnetization_curve!N6,Initial_magnetization_curve!Q6)/AVERAGE(Initial_magnetization_curve!K6,Initial_magnetization_curve!N6,Initial_magnetization_curve!Q6)*100 | D3: =AVERAGE(Initial_magnetization_curve!D6,Initial_magnetization_curve!G6,Initial_magnetization_curve!J6,Initial_magnetization_curve!M6,Initial_magnetization_curve!P6,A3) | E3: =STDEV(Initial_magnetization_curve!B6,Initial_magnetization_curve!E6,Initial_magnetization_curve!H6,Initial_magnetization_curve!K6,Initial_magnetization_curve!N6,Initial_magnetization_curve!Q6)/AVERAGE(Initial_magnetization_curve!B6,Initial_magnetization_curve!E6,Initial_magnetization_curve!H6,Initial_magnetization_curve!K6,Initial_magnetization_curve!N6,Initial_magnetization_curve!Q6)*100 | F3: =AVERAGE(Initial_magnetization_curve!A47,Initial_magnetization_curve!D47,Initial_magnetization_curve!G47,Initial_magnetization_curve!J47,Initial_magnetization_curve!M47,Initial_magnetization_curve!P47) | G3: =STDEV(Initial_magnetization_curve!E47,Initial_magnetization_curve!N47)/AVERAGE(Initial_magnetization_curve!E47,Initial_magnetization_curve!N47)*100 | H3: =AVERAGE(Initial_magnetization_curve!A88,Initial_magnetization_curve!D88,Initial_magnetization_curve!G88,Initial_magnetization_curve!J88,Initial_magnetization_curve!M88,Initial_magnetization_curve!P88) | I3: =STDEV(Initial_magnetization_curve!E88,Initial_magnetization_curve!N88)/AVERAGE(Initial_magnetization_curve!E88,Initial_magnetization_curve!N88)*100 | J3: =AVERAGE(Initial_magnetization_curve!D6,Initial_magnetization_curve!G6,Initial_magnetization_curve!J6,Initial_magnetization_curve!M6,Initial_magnetization_curve!P6,A3,Initial_magnetization_curve!D47,Initial_magnetization_curve!M47,Initial_magnetization_curve!D88,Initial_magnetization_curve!M88) | K3: =STDEV(Initial_magnetization_curve!B6,Initial_magnetization_curve!E6,Initial_magnetization_curve!H6,Initial_magnetization_curve!K6,Initial_magnetization_curve!N6,Initial_magnetization_curve!Q6,Initial_magnetization_curve!E47,Initial_magnetization_curve!N47,Initial_magnetization_curve!E88,Initial_magnetization_curve!N88)/AVERAGE(Initial_magnetization_curve!B6,Initial_magnetization_curve!E6,Initial_magnetization_curve!H6,Initial_magnetization_curve!K6,Initial_magnetization_curve!N6,Initial_magnetization_curve!Q6,Initial_magnetization_curve!E47,Initial_magnetization_curve!N47,Initial_magnetization_curve!E88,Initial_magnetization_curve!N88)*100
A4: =AVERAGE(Initial_magnetization_curve!A7,Initial_magnetization_curve!D7,Initial_magnetization_curve!G7,Initial_magnetization_curve!J7,Initial_magnetization_curve!M7,Initial_magnetization_curve!P7) | B4: =STDEV(Initial_magnetization_curve!B7,Initial_magnetization_curve!E7,Initial_magnetization_curve!H7)/AVERAGE(Initial_magnetization_curve!B7,Initial_magnetization_curve!E7,Initial_magnetization_curve!H7)*100 | C4: =STDEV(Initial_magnetization_curve!K7,Initial_magnetization_curve!N7,Initial_magnetization_curve!Q7)/AVERAGE(Initial_magnetization_curve!K7,Initial_magnetization_curve!N7,Initial_magnetization_curve!Q7)*100 | D4: =AVERAGE(Initial_magnetization_curve!D7,Initial_magnetization_curve!G7,Initial_magnetization_curve!J7,Initial_magnetization_curve!M7,Initial_magnetization_curve!P7,A4) | E4: =STDEV(Initial_magnetization_curve!B7,Initial_magnetization_curve!E7,Initial_magnetization_curve!H7,Initial_magnetization_curve!K7,Initial_magnetization_curve!N7,Initial_magnetization_curve!Q7)/AVERAGE(Initial_magnetization_curve!B7,Initial_magnetization_curve!E7,Initial_magnetization_curve!H7,Initial_magnetization_curve!K7,Initial_magnetization_curve!N7,Initial_magnetization_curve!Q7)*100 | F4: =AVERAGE(Initial_magnetization_curve!A48,Initial_magnetization_curve!D48,Initial_magnetization_curve!G48,Initial_magnetization_curve!J48,Initial_magnetization_curve!M48,Initial_magnetization_curve!P48) | G4: =STDEV(Initial_magnetization_curve!E48,Initial_magnetization_curve!N48)/AVERAGE(Initial_magnetization_curve!E48,Initial_magnetization_curve!N48)*100 | H4: =AVERAGE(Initial_magnetization_curve!A89,Initial_magnetization_curve!D89,Initial_magnetization_curve!G89,Initial_magnetization_curve!J89,Initial_magnetization_curve!M89,Initial_magnetization_curve!P89) | I4: =STDEV(Initial_magnetization_curve!E89,Initial_magnetization_curve!N89)/AVERAGE(Initial_magnetization_curve!E89,Initial_magnetization_curve!N89)*100 | J4: =AVERAGE(Initial_magnetization_curve!D7,Initial_magnetization_curve!G7,Initial_magnetization_curve!J7,Initial_magnetization_curve!M7,Initial_magnetization_curve!P7,A4,Initial_magnetization_curve!D48,Initial_magnetization_curve!M48,Initial_magnetization_curve!D89,Initial_magnetization_curve!M89) | K4: =STDEV(Initial_magnetization_curve!B7,Initial_magnetization_curve!E7,Initial_magnetization_curve!H7,Initial_magnetization_curve!K7,Initial_magnetization_curve!N7,Initial_magnetization_curve!Q7,Initial_magnetization_curve!E48,Initial_magnetization_curve!N48,Initial_magnetization_curve!E89,Initial_magnetization_curve!N89)/AVERAGE(Initial_magnetization_curve!B7,Initial_magnetization_curve!E7,Initial_magnetization_curve!H7,Initial_magnetization_curve!K7,Initial_magnetization_curve!N7,Initial_magnetization_curve!Q7,Initial_magnetization_curve!E48,Initial_magnetization_curve!N48,Initial_magnetization_curve!E89,Initial_magnetization_curve!N89)*100
A5: =AVERAGE(Initial_magnetization_curve!A8,Initial_magnetization_curve!D8,Initial_magnetization_curve!G8,Initial_magnetization_curve!J8,Initial_magnetization_curve!M8,Initial_magnetization_curve!P8) | B5: =STDEV(Initial_magnetization_curve!B8,Initial_magnetization_curve!E8,Initial_magnetization_curve!H8)/AVERAGE(Initial_magnetization_curve!B8,Initial_magnetization_curve!E8,Initial_magnetization_curve!H8)*100 | C5: =STDEV(Initial_magnetization_curve!K8,Initial_magnetization_curve!N8,Initial_magnetization_curve!Q8)/AVERAGE(Initial_magnetization_curve!K8,Initial_magnetization_curve!N8,Initial_magnetization_curve!Q8)*100 | D5: =AVERAGE(Initial_magnetization_curve!D8,Initial_magnetization_curve!G8,Initial_magnetization_curve!J8,Initial_magnetization_curve!M8,Initial_magnetization_curve!P8,A5) | E5: =STDEV(Initial_magnetization_curve!B8,Initial_magnetization_curve!E8,Initial_magnetization_curve!H8,Initial_magnetization_curve!K8,Initial_magnetization_curve!N8,Initial_magnetization_curve!Q8)/AVERAGE(Initial_magnetization_curve!B8,Initial_magnetization_curve!E8,Initial_magnetization_curve!H8,Initial_magnetization_curve!K8,Initial_magnetization_curve!N8,Initial_magnetization_curve!Q8)*100 | F5: =AVERAGE(Initial_magnetization_curve!A49,Initial_magnetization_curve!D49,Initial_magnetization_curve!G49,Initial_magnetization_curve!J49,Initial_magnetization_curve!M49,Initial_magnetization_curve!P49) | G5: =STDEV(Initial_magnetization_curve!E49,Initial_magnetization_curve!N49)/AVERAGE(Initial_magnetization_curve!E49,Initial_magnetization_curve!N49)*100 | H5: =AVERAGE(Initial_magnetization_curve!A90,Initial_magnetization_curve!D90,Initial_magnetization_curve!G90,Initial_magnetization_curve!J90,Initial_magnetization_curve!M90,Initial_magnetization_curve!P90) | I5: =STDEV(Initial_magnetization_curve!E90,Initial_magnetization_curve!N90)/AVERAGE(Initial_magnetization_curve!E90,Initial_magnetization_curve!N90)*100 | J5: =AVERAGE(Initial_magnetization_curve!D8,Initial_magnetization_curve!G8,Initial_magnetization_curve!J8,Initial_magnetization_curve!M8,Initial_magnetization_curve!P8,A5,Initial_magnetization_curve!D49,Initial_magnetization_curve!M49,Initial_magnetization_curve!D90,Initial_magnetization_curve!M90) | K5: =STDEV(Initial_magnetization_curve!B8,Initial_magnetization_curve!E8,Initial_magnetization_curve!H8,Initial_magnetization_curve!K8,Initial_magnetization_curve!N8,Initial_magnetization_curve!Q8,Initial_magnetization_curve!E49,Initial_magnetization_curve!N49,Initial_magnetization_curve!E90,Initial_magnetization_curve!N90)/AVERAGE(Initial_magnetization_curve!B8,Initial_magnetization_curve!E8,Initial_magnetization_curve!H8,Initial_magnetization_curve!K8,Initial_magnetization_curve!N8,Initial_magnetization_curve!Q8,Initial_magnetization_curve!E49,Initial_magnetization_curve!N49,Initial_magnetization_curve!E90,Initial_magnetization_curve!N90)*100
A6: =AVERAGE(Initial_magnetization_curve!A9,Initial_magnetization_curve!D9,Initial_magnetization_curve!G9,Initial_magnetization_curve!J9,Initial_magnetization_curve!M9,Initial_magnetization_curve!P9) | B6: =STDEV(Initial_magnetization_curve!B9,Initial_magnetization_curve!E9,Initial_magnetization_curve!H9)/AVERAGE(Initial_magnetization_curve!B9,Initial_magnetization_curve!E9,Initial_magnetization_curve!H9)*100 | C6: =STDEV(Initial_magnetization_curve!K9,Initial_magnetization_curve!N9,Initial_magnetization_curve!Q9)/AVERAGE(Initial_magnetization_curve!K9,Initial_magnetization_curve!N9,Initial_magnetization_curve!Q9)*100 | D6: =AVERAGE(Initial_magnetization_curve!D9,Initial_magnetization_curve!G9,Initial_magnetization_curve!J9,Initial_magnetization_curve!M9,Initial_magnetization_curve!P9,A6) | E6: =STDEV(Initial_magnetization_curve!B9,Initial_magnetization_curve!E9,Initial_magnetization_curve!H9,Initial_magnetization_curve!K9,Initial_magnetization_curve!N9,Initial_magnetization_curve!Q9)/AVERAGE(Initial_magnetization_curve!B9,Initial_magnetization_curve!E9,Initial_magnetization_curve!H9,Initial_magnetization_curve!K9,Initial_magnetization_curve!N9,Initial_magnetization_curve!Q9)*100 | F6: =AVERAGE(Initial_magnetization_curve!A50,Initial_magnetization_curve!D50,Initial_magnetization_curve!G50,Initial_magnetization_curve!J50,Initial_magnetization_curve!M50,Initial_magnetization_curve!P50) | G6: =STDEV(Initial_magnetization_curve!E50,Initial_magnetization_curve!N50)/AVERAGE(Initial_magnetization_curve!E50,Initial_magnetization_curve!N50)*100 | H6: =AVERAGE(Initial_magnetization_curve!A91,Initial_magnetization_curve!D91,Initial_magnetization_curve!G91,Initial_magnetization_curve!J91,Initial_magnetization_curve!M91,Initial_magnetization_curve!P91) | I6: =STDEV(Initial_magnetization_curve!E91,Initial_magnetization_curve!N91)/AVERAGE(Initial_magnetization_curve!E91,Initial_magnetization_curve!N91)*100 | J6: =AVERAGE(Initial_magnetization_curve!D9,Initial_magnetization_curve!G9,Initial_magnetization_curve!J9,Initial_magnetization_curve!M9,Initial_magnetization_curve!P9,A6,Initial_magnetization_curve!D50,Initial_magnetization_curve!M50,Initial_magnetization_curve!D91,Initial_magnetization_curve!M91) | K6: =STDEV(Initial_magnetization_curve!B9,Initial_magnetization_curve!E9,Initial_magnetization_curve!H9,Initial_magnetization_curve!K9,Initial_magnetization_curve!N9,Initial_magnetization_curve!Q9,Initial_magnetization_curve!E50,Initial_magnetization_curve!N50,Initial_magnetization_curve!E91,Initial_magnetization_curve!N91)/AVERAGE(Initial_magnetization_curve!B9,Initial_magnetization_curve!E9,Initial_magnetization_curve!H9,Initial_magnetization_curve!K9,Initial_magnetization_curve!N9,Initial_magnetization_curve!Q9,Initial_magnetization_curve!E50,Initial_magnetization_curve!N50,Initial_magnetization_curve!E91,Initial_magnetization_curve!N91)*100
A7: =AVERAGE(Initial_magnetization_curve!A10,Initial_magnetization_curve!D10,Initial_magnetization_curve!G10,Initial_magnetization_curve!J10,Initial_magnetization_curve!M10,Initial_magnetization_curve!P10) | B7: =STDEV(Initial_magnetization_curve!B10,Initial_magnetization_curve!E10,Initial_magnetization_curve!H10)/AVERAGE(Initial_magnetization_curve!B10,Initial_magnetization_curve!E10,Initial_magnetization_curve!H10)*100 | C7: =STDEV(Initial_magnetization_curve!K10,Initial_magnetization_curve!N10,Initial_magnetization_curve!Q10)/AVERAGE(Initial_magnetization_curve!K10,Initial_magnetization_curve!N10,Initial_magnetization_curve!Q10)*100 | D7: =AVERAGE(Initial_magnetization_curve!D10,Initial_magnetization_curve!G10,Initial_magnetization_curve!J10,Initial_magnetization_curve!M10,Initial_magnetization_curve!P10,A7) | E7: =STDEV(Initial_magnetization_curve!B10,Initial_magnetization_curve!E10,Initial_magnetization_curve!H10,Initial_magnetization_curve!K10,Initial_magnetization_curve!N10,Initial_magnetization_curve!Q10)/AVERAGE(Initial_magnetization_curve!B10,Initial_magnetization_curve!E10,Initial_magnetization_curve!H10,Initial_magnetization_curve!K10,Initial_magnetization_curve!N10,Initial_magnetization_curve!Q10)*100 | F7: =AVERAGE(Initial_magnetization_curve!A51,Initial_magnetization_curve!D51,Initial_magnetization_curve!G51,Initial_magnetization_curve!J51,Initial_magnetization_curve!M51,Initial_magnetization_curve!P51) | G7: =STDEV(Initial_magnetization_curve!E51,Initial_magnetization_curve!N51)/AVERAGE(Initial_magnetization_curve!E51,Initial_magnetization_curve!N51)*100 | H7: =AVERAGE(Initial_magnetization_curve!A92,Initial_magnetization_curve!D92,Initial_magnetization_curve!G92,Initial_magnetization_curve!J92,Initial_magnetization_curve!M92,Initial_magnetization_curve!P92) | I7: =STDEV(Initial_magnetization_curve!E92,Initial_magnetization_curve!N92)/AVERAGE(Initial_magnetization_curve!E92,Initial_magnetization_curve!N92)*100 | J7: =AVERAGE(Initial_magnetization_curve!D10,Initial_magnetization_curve!G10,Initial_magnetization_curve!J10,Initial_magnetization_curve!M10,Initial_magnetization_curve!P10,A7,Initial_magnetization_curve!D51,Initial_magnetization_curve!M51,Initial_magnetization_curve!D92,Initial_magnetization_curve!M92) | K7: =STDEV(Initial_magnetization_curve!B10,Initial_magnetization_curve!E10,Initial_magnetization_curve!H10,Initial_magnetization_curve!K10,Initial_magnetization_curve!N10,Initial_magnetization_curve!Q10,Initial_magnetization_curve!E51,Initial_magnetization_curve!N51,Initial_magnetization_curve!E92,Initial_magnetization_curve!N92)/AVERAGE(Initial_magnetization_curve!B10,Initial_magnetization_curve!E10,Initial_magnetization_curve!H10,Initial_magnetization_curve!K10,Initial_magnetization_curve!N10,Initial_magnetization_curve!Q10,Initial_magnetization_curve!E51,Initial_magnetization_curve!N51,Initial_magnetization_curve!E92,Initial_magnetization_curve!N92)*100
A8: =AVERAGE(Initial_magnetization_curve!A11,Initial_magnetization_curve!D11,Initial_magnetization_curve!G11,Initial_magnetization_curve!J11,Initial_magnetization_curve!M11,Initial_magnetization_curve!P11) | B8: =STDEV(Initial_magnetization_curve!B11,Initial_magnetization_curve!E11,Initial_magnetization_curve!H11)/AVERAGE(Initial_magnetization_curve!B11,Initial_magnetization_curve!E11,Initial_magnetization_curve!H11)*100 | C8: =STDEV(Initial_magnetization_curve!K11,Initial_magnetization_curve!N11,Initial_magnetization_curve!Q11)/AVERAGE(Initial_magnetization_curve!K11,Initial_magnetization_curve!N11,Initial_magnetization_curve!Q11)*100 | D8: =AVERAGE(Initial_magnetization_curve!D11,Initial_magnetization_curve!G11,Initial_magnetization_curve!J11,Initial_magnetization_curve!M11,Initial_magnetization_curve!P11,A8) | E8: =STDEV(Initial_magnetization_curve!B11,Initial_magnetization_curve!E11,Initial_magnetization_curve!H11,Initial_magnetization_curve!K11,Initial_magnetization_curve!N11,Initial_magnetization_curve!Q11)/AVERAGE(Initial_magnetization_curve!B11,Initial_magnetization_curve!E11,Initial_magnetization_curve!H11,Initial_magnetization_curve!K11,Initial_magnetization_curve!N11,Initial_magnetization_curve!Q11)*100 | F8: =AVERAGE(Initial_magnetization_curve!A52,Initial_magnetization_curve!D52,Initial_magnetization_curve!G52,Initial_magnetization_curve!J52,Initial_magnetization_curve!M52,Initial_magnetization_curve!P52) | G8: =STDEV(Initial_magnetization_curve!E52,Initial_magnetization_curve!N52)/AVERAGE(Initial_magnetization_curve!E52,Initial_magnetization_curve!N52)*100 | H8: =AVERAGE(Initial_magnetization_curve!A93,Initial_magnetization_curve!D93,Initial_magnetization_curve!G93,Initial_magnetization_curve!J93,Initial_magnetization_curve!M93,Initial_magnetization_curve!P93) | I8: =STDEV(Initial_magnetization_curve!E93,Initial_magnetization_curve!N93)/AVERAGE(Initial_magnetization_curve!E93,Initial_magnetization_curve!N93)*100 | J8: =AVERAGE(Initial_magnetization_curve!D11,Initial_magnetization_curve!G11,Initial_magnetization_curve!J11,Initial_magnetization_curve!M11,Initial_magnetization_curve!P11,A8,Initial_magnetization_curve!D52,Initial_magnetization_curve!M52,Initial_magnetization_curve!D93,Initial_magnetization_curve!M93) | K8: =STDEV(Initial_magnetization_curve!B11,Initial_magnetization_curve!E11,Initial_magnetization_curve!H11,Initial_magnetization_curve!K11,Initial_magnetization_curve!N11,Initial_magnetization_curve!Q11,Initial_magnetization_curve!E52,Initial_magnetization_curve!N52,Initial_magnetization_curve!E93,Initial_magnetization_curve!N93)/AVERAGE(Initial_magnetization_curve!B11,Initial_magnetization_curve!E11,Initial_magnetization_curve!H11,Initial_magnetization_curve!K11,Initial_magnetization_curve!N11,Initial_magnetization_curve!Q11,Initial_magnetization_curve!E52,Initial_magnetization_curve!N52,Initial_magnetization_curve!E93,Initial_magnetization_curve!N93)*100
A9: =AVERAGE(Initial_magnetization_curve!A12,Initial_magnetization_curve!D12,Initial_magnetization_curve!G12,Initial_magnetization_curve!J12,Initial_magnetization_curve!M12,Initial_magnetization_curve!P12) | B9: =STDEV(Initial_magnetization_curve!B12,Initial_magnetization_curve!E12,Initial_magnetization_curve!H12)/AVERAGE(Initial_magnetization_curve!B12,Initial_magnetization_curve!E12,Initial_magnetization_curve!H12)*100 | C9: =STDEV(Initial_magnetization_curve!K12,Initial_magnetization_curve!N12,Initial_magnetization_curve!Q12)/AVERAGE(Initial_magnetization_curve!K12,Initial_magnetization_curve!N12,Initial_magnetization_curve!Q12)*100 | D9: =AVERAGE(Initial_magnetization_curve!D12,Initial_magnetization_curve!G12,Initial_magnetization_curve!J12,Initial_magnetization_curve!M12,Initial_magnetization_curve!P12,A9) | E9: =STDEV(Initial_magnetization_curve!B12,Initial_magnetization_curve!E12,Initial_magnetization_curve!H12,Initial_magnetization_curve!K12,Initial_magnetization_curve!N12,Initial_magnetization_curve!Q12)/AVERAGE(Initial_magnetization_curve!B12,Initial_magnetization_curve!E12,Initial_magnetization_curve!H12,Initial_magnetization_curve!K12,Initial_magnetization_curve!N12,Initial_magnetization_curve!Q12)*100 | F9: =AVERAGE(Initial_magnetization_curve!A53,Initial_magnetization_curve!D53,Initial_magnetization_curve!G53,Initial_magnetization_curve!J53,Initial_magnetization_curve!M53,Initial_magnetization_curve!P53) | G9: =STDEV(Initial_magnetization_curve!E53,Initial_magnetization_curve!N53)/AVERAGE(Initial_magnetization_curve!E53,Initial_magnetization_curve!N53)*100 | H9: =AVERAGE(Initial_magnetization_curve!A94,Initial_magnetization_curve!D94,Initial_magnetization_curve!G94,Initial_magnetization_curve!J94,Initial_magnetization_curve!M94,Initial_magnetization_curve!P94) | I9: =STDEV(Initial_magnetization_curve!E94,Initial_magnetization_curve!N94)/AVERAGE(Initial_magnetization_curve!E94,Initial_magnetization_curve!N94)*100 | J9: =AVERAGE(Initial_magnetization_curve!D12,Initial_magnetization_curve!G12,Initial_magnetization_curve!J12,Initial_magnetization_curve!M12,Initial_magnetization_curve!P12,A9,Initial_magnetization_curve!D53,Initial_magnetization_curve!M53,Initial_magnetization_curve!D94,Initial_magnetization_curve!M94) | K9: =STDEV(Initial_magnetization_curve!B12,Initial_magnetization_curve!E12,Initial_magnetization_curve!H12,Initial_magnetization_curve!K12,Initial_magnetization_curve!N12,Initial_magnetization_curve!Q12,Initial_magnetization_curve!E53,Initial_magnetization_curve!N53,Initial_magnetization_curve!E94,Initial_magnetization_curve!N94)/AVERAGE(Initial_magnetization_curve!B12,Initial_magnetization_curve!E12,Initial_magnetization_curve!H12,Initial_magnetization_curve!K12,Initial_magnetization_curve!N12,Initial_magnetization_curve!Q12,Initial_magnetization_curve!E53,Initial_magnetization_curve!N53,Initial_magnetization_curve!E94,Initial_magnetization_curve!N94)*100
A10: =AVERAGE(Initial_magnetization_curve!A13,Initial_magnetization_curve!D13,Initial_magnetization_curve!G13,Initial_magnetization_curve!J13,Initial_magnetization_curve!M13,Initial_magnetization_curve!P13) | B10: =STDEV(Initial_magnetization_curve!B13,Initial_magnetization_curve!E13,Initial_magnetization_curve!H13)/AVERAGE(Initial_magnetization_curve!B13,Initial_magnetization_curve!E13,Initial_magnetization_curve!H13)*100 | C10: =STDEV(Initial_magnetization_curve!K13,Initial_magnetization_curve!N13,Initial_magnetization_curve!Q13)/AVERAGE(Initial_magnetization_curve!K13,Initial_magnetization_curve!N13,Initial_magnetization_curve!Q13)*100 | D10: =AVERAGE(Initial_magnetization_curve!D13,Initial_magnetization_curve!G13,Initial_magnetization_curve!J13,Initial_magnetization_curve!M13,Initial_magnetization_curve!P13,A10) | E10: =STDEV(Initial_magnetization_curve!B13,Initial_magnetization_curve!E13,Initial_magnetization_curve!H13,Initial_magnetization_curve!K13,Initial_magnetization_curve!N13,Initial_magnetization_curve!Q13)/AVERAGE(Initial_magnetization_curve!B13,Initial_magnetization_curve!E13,Initial_magnetization_curve!H13,Initial_magnetization_curve!K13,Initial_magnetization_curve!N13,Initial_magnetization_curve!Q13)*100 | F10: =AVERAGE(Initial_magnetization_curve!A54,Initial_magnetization_curve!D54,Initial_magnetization_curve!G54,Initial_magnetization_curve!J54,Initial_magnetization_curve!M54,Initial_magnetization_curve!P54) | G10: =STDEV(Initial_magnetization_curve!E54,Initial_magnetization_curve!N54)/AVERAGE(Initial_magnetization_curve!E54,Initial_magnetization_curve!N54)*100 | H10: =AVERAGE(Initial_magnetization_curve!A95,Initial_magnetization_curve!D95,Initial_magnetization_curve!G95,Initial_magnetization_curve!J95,Initial_magnetization_curve!M95,Initial_magnetization_curve!P95) | I10: =STDEV(Initial_magnetization_curve!E95,Initial_magnetization_curve!N95)/AVERAGE(Initial_magnetization_curve!E95,Initial_magnetization_curve!N95)*100 | J10: =AVERAGE(Initial_magnetization_curve!D13,Initial_magnetization_curve!G13,Initial_magnetization_curve!J13,Initial_magnetization_curve!M13,Initial_magnetization_curve!P13,A10,Initial_magnetization_curve!D54,Initial_magnetization_curve!M54,Initial_magnetization_curve!D95,Initial_magnetization_curve!M95) | K10: =STDEV(Initial_magnetization_curve!B13,Initial_magnetization_curve!E13,Initial_magnetization_curve!H13,Initial_magnetization_curve!K13,Initial_magnetization_curve!N13,Initial_magnetization_curve!Q13,Initial_magnetization_curve!E54,Initial_magnetization_curve!N54,Initial_magnetization_curve!E95,Initial_magnetization_curve!N95)/AVERAGE(Initial_magnetization_curve!B13,Initial_magnetization_curve!E13,Initial_magnetization_curve!H13,Initial_magnetization_curve!K13,Initial_magnetization_curve!N13,Initial_magnetization_curve!Q13,Initial_magnetization_curve!E54,Initial_magnetization_curve!N54,Initial_magnetization_curve!E95,Initial_magnetization_curve!N95)*100
A11: =AVERAGE(Initial_magnetization_curve!A14,Initial_magnetization_curve!D14,Initial_magnetization_curve!G14,Initial_magnetization_curve!J14,Initial_magnetization_curve!M14,Initial_magnetization_curve!P14) | B11: =STDEV(Initial_magnetization_curve!B14,Initial_magnetization_curve!E14,Initial_magnetization_curve!H14)/AVERAGE(Initial_magnetization_curve!B14,Initial_magnetization_curve!E14,Initial_magnetization_curve!H14)*100 | C11: =STDEV(Initial_magnetization_curve!K14,Initial_magnetization_curve!N14,Initial_magnetization_curve!Q14)/AVERAGE(Initial_magnetization_curve!K14,Initial_magnetization_curve!N14,Initial_magnetization_curve!Q14)*100 | D11: =AVERAGE(Initial_magnetization_curve!D14,Initial_magnetization_curve!G14,Initial_magnetization_curve!J14,Initial_magnetization_curve!M14,Initial_magnetization_curve!P14,A11) | E11: =STDEV(Initial_magnetization_curve!B14,Initial_magnetization_curve!E14,Initial_magnetization_curve!H14,Initial_magnetization_curve!K14,Initial_magnetization_curve!N14,Initial_magnetization_curve!Q14)/AVERAGE(Initial_magnetization_curve!B14,Initial_magnetization_curve!E14,Initial_magnetization_curve!H14,Initial_magnetization_curve!K14,Initial_magnetization_curve!N14,Initial_magnetization_curve!Q14)*100 | F11: =AVERAGE(Initial_magnetization_curve!A55,Initial_magnetization_curve!D55,Initial_magnetization_curve!G55,Initial_magnetization_curve!J55,Initial_magnetization_curve!M55,Initial_magnetization_curve!P55) | G11: =STDEV(Initial_magnetization_curve!E55,Initial_magnetization_curve!N55)/AVERAGE(Initial_magnetization_curve!E55,Initial_magnetization_curve!N55)*100 | H11: =AVERAGE(Initial_magnetization_curve!A96,Initial_magnetization_curve!D96,Initial_magnetization_curve!G96,Initial_magnetization_curve!J96,Initial_magnetization_curve!M96,Initial_magnetization_curve!P96) | I11: =STDEV(Initial_magnetization_curve!E96,Initial_magnetization_curve!N96)/AVERAGE(Initial_magnetization_curve!E96,Initial_magnetization_curve!N96)*100 | J11: =AVERAGE(Initial_magnetization_curve!D14,Initial_magnetization_curve!G14,Initial_magnetization_curve!J14,Initial_magnetization_curve!M14,Initial_magnetization_curve!P14,A11,Initial_magnetization_curve!D55,Initial_magnetization_curve!M55,Initial_magnetization_curve!D96,Initial_magnetization_curve!M96) | K11: =STDEV(Initial_magnetization_curve!B14,Initial_magnetization_curve!E14,Initial_magnetization_curve!H14,Initial_magnetization_curve!K14,Initial_magnetization_curve!N14,Initial_magnetization_curve!Q14,Initial_magnetization_curve!E55,Initial_magnetization_curve!N55,Initial_magnetization_curve!E96,Initial_magnetization_curve!N96)/AVERAGE(Initial_magnetization_curve!B14,Initial_magnetization_curve!E14,Initial_magnetization_curve!H14,Initial_magnetization_curve!K14,Initial_magnetization_curve!N14,Initial_magnetization_curve!Q14,Initial_magnetization_curve!E55,Initial_magnetization_curve!N55,Initial_magnetization_curve!E96,Initial_magnetization_curve!N96)*100
A12: =AVERAGE(Initial_magnetization_curve!A15,Initial_magnetization_curve!D15,Initial_magnetization_curve!G15,Initial_magnetization_curve!J15,Initial_magnetization_curve!M15,Initial_magnetization_curve!P15) | B12: =STDEV(Initial_magnetization_curve!B15,Initial_magnetization_curve!E15,Initial_magnetization_curve!H15)/AVERAGE(Initial_magnetization_curve!B15,Initial_magnetization_curve!E15,Initial_magnetization_curve!H15)*100 | C12: =STDEV(Initial_magnetization_curve!K15,Initial_magnetization_curve!N15,Initial_magnetization_curve!Q15)/AVERAGE(Initial_magnetization_curve!K15,Initial_magnetization_curve!N15,Initial_magnetization_curve!Q15)*100 | D12: =AVERAGE(Initial_magnetization_curve!D15,Initial_magnetization_curve!G15,Initial_magnetization_curve!J15,Initial_magnetization_curve!M15,Initial_magnetization_curve!P15,A12) | E12: =STDEV(Initial_magnetization_curve!B15,Initial_magnetization_curve!E15,Initial_magnetization_curve!H15,Initial_magnetization_curve!K15,Initial_magnetization_curve!N15,Initial_magnetization_curve!Q15)/AVERAGE(Initial_magnetization_curve!B15,Initial_magnetization_curve!E15,Initial_magnetization_curve!H15,Initial_magnetization_curve!K15,Initial_magnetization_curve!N15,Initial_magnetization_curve!Q15)*100 | F12: =AVERAGE(Initial_magnetization_curve!A56,Initial_magnetization_curve!D56,Initial_magnetization_curve!G56,Initial_magnetization_curve!J56,Initial_magnetization_curve!M56,Initial_magnetization_curve!P56) | G12: =STDEV(Initial_magnetization_curve!E56,Initial_magnetization_curve!N56)/AVERAGE(Initial_magnetization_curve!E56,Initial_magnetization_curve!N56)*100 | H12: =AVERAGE(Initial_magnetization_curve!A97,Initial_magnetization_curve!D97,Initial_magnetization_curve!G97,Initial_magnetization_curve!J97,Initial_magnetization_curve!M97,Initial_magnetization_curve!P97) | I12: =STDEV(Initial_magnetization_curve!E97,Initial_magnetization_curve!N97)/AVERAGE(Initial_magnetization_curve!E97,Initial_magnetization_curve!N97)*100 | J12: =AVERAGE(Initial_magnetization_curve!D15,Initial_magnetization_curve!G15,Initial_magnetization_curve!J15,Initial_magnetization_curve!M15,Initial_magnetization_curve!P15,A12,Initial_magnetization_curve!D56,Initial_magnetization_curve!M56,Initial_magnetization_curve!D97,Initial_magnetization_curve!M97) | K12: =STDEV(Initial_magnetization_curve!B15,Initial_magnetization_curve!E15,Initial_magnetization_curve!H15,Initial_magnetization_curve!K15,Initial_magnetization_curve!N15,Initial_magnetization_curve!Q15,Initial_magnetization_curve!E56,Initial_magnetization_curve!N56,Initial_magnetization_curve!E97,Initial_magnetization_curve!N97)/AVERAGE(Initial_magnetization_curve!B15,Initial_magnetization_curve!E15,Initial_magnetization_curve!H15,Initial_magnetization_curve!K15,Initial_magnetization_curve!N15,Initial_magnetization_curve!Q15,Initial_magnetization_curve!E56,Initial_magnetization_curve!N56,Initial_magnetization_curve!E97,Initial_magnetization_curve!N97)*100
A13: =AVERAGE(Initial_magnetization_curve!A16,Initial_magnetization_curve!D16,Initial_magnetization_curve!G16,Initial_magnetization_curve!J16,Initial_magnetization_curve!M16,Initial_magnetization_curve!P16) | B13: =STDEV(Initial_magnetization_curve!B16,Initial_magnetization_curve!E16,Initial_magnetization_curve!H16)/AVERAGE(Initial_magnetization_curve!B16,Initial_magnetization_curve!E16,Initial_magnetization_curve!H16)*100 | C13: =STDEV(Initial_magnetization_curve!K16,Initial_magnetization_curve!N16,Initial_magnetization_curve!Q16)/AVERAGE(Initial_magnetization_curve!K16,Initial_magnetization_curve!N16,Initial_magnetization_curve!Q16)*100 | D13: =AVERAGE(Initial_magnetization_curve!D16,Initial_magnetization_curve!G16,Initial_magnetization_curve!J16,Initial_magnetization_curve!M16,Initial_magnetization_curve!P16,A13) | E13: =STDEV(Initial_magnetization_curve!B16,Initial_magnetization_curve!E16,Initial_magnetization_curve!H16,Initial_magnetization_curve!K16,Initial_magnetization_curve!N16,Initial_magnetization_curve!Q16)/AVERAGE(Initial_magnetization_curve!B16,Initial_magnetization_curve!E16,Initial_magnetization_curve!H16,Initial_magnetization_curve!K16,Initial_magnetization_curve!N16,Initial_magnetization_curve!Q16)*100 | F13: =AVERAGE(Initial_magnetization_curve!A57,Initial_magnetization_curve!D57,Initial_magnetization_curve!G57,Initial_magnetization_curve!J57,Initial_magnetization_curve!M57,Initial_magnetization_curve!P57) | G13: =STDEV(Initial_magnetization_curve!E57,Initial_magnetization_curve!N57)/AVERAGE(Initial_magnetization_curve!E57,Initial_magnetization_curve!N57)*100 | H13: =AVERAGE(Initial_magnetization_curve!A98,Initial_magnetization_curve!D98,Initial_magnetization_curve!G98,Initial_magnetization_curve!J98,Initial_magnetization_curve!M98,Initial_magnetization_curve!P98) | I13: =STDEV(Initial_magnetization_curve!E98,Initial_magnetization_curve!N98)/AVERAGE(Initial_magnetization_curve!E98,Initial_magnetization_curve!N98)*100 | J13: =AVERAGE(Initial_magnetization_curve!D16,Initial_magnetization_curve!G16,Initial_magnetization_curve!J16,Initial_magnetization_curve!M16,Initial_magnetization_curve!P16,A13,Initial_magnetization_curve!D57,Initial_magnetization_curve!M57,Initial_magnetization_curve!D98,Initial_magnetization_curve!M98) | K13: =STDEV(Initial_magnetization_curve!B16,Initial_magnetization_curve!E16,Initial_magnetization_curve!H16,Initial_magnetization_curve!K16,Initial_magnetization_curve!N16,Initial_magnetization_curve!Q16,Initial_magnetization_curve!E57,Initial_magnetization_curve!N57,Initial_magnetization_curve!E98,Initial_magnetization_curve!N98)/AVERAGE(Initial_magnetization_curve!B16,Initial_magnetization_curve!E16,Initial_magnetization_curve!H16,Initial_magnetization_curve!K16,Initial_magnetization_curve!N16,Initial_magnetization_curve!Q16,Initial_magnetization_curve!E57,Initial_magnetization_curve!N57,Initial_magnetization_curve!E98,Initial_magnetization_curve!N98)*100
A14: =AVERAGE(Initial_magnetization_curve!A17,Initial_magnetization_curve!D17,Initial_magnetization_curve!G17,Initial_magnetization_curve!J17,Initial_magnetization_curve!M17,Initial_magnetization_curve!P17) | B14: =STDEV(Initial_magnetization_curve!B17,Initial_magnetization_curve!E17,Initial_magnetization_curve!H17)/AVERAGE(Initial_magnetization_curve!B17,Initial_magnetization_curve!E17,Initial_magnetization_curve!H17)*100 | C14: =STDEV(Initial_magnetization_curve!K17,Initial_magnetization_curve!N17,Initial_magnetization_curve!Q17)/AVERAGE(Initial_magnetization_curve!K17,Initial_magnetization_curve!N17,Initial_magnetization_curve!Q17)*100 | D14: =AVERAGE(Initial_magnetization_curve!D17,Initial_magnetization_curve!G17,Initial_magnetization_curve!J17,Initial_magnetization_curve!M17,Initial_magnetization_curve!P17,A14) | E14: =STDEV(Initial_magnetization_curve!B17,Initial_magnetization_curve!E17,Initial_magnetization_curve!H17,Initial_magnetization_curve!K17,Initial_magnetization_curve!N17,Initial_magnetization_curve!Q17)/AVERAGE(Initial_magnetization_curve!B17,Initial_magnetization_curve!E17,Initial_magnetization_curve!H17,Initial_magnetization_curve!K17,Initial_magnetization_curve!N17,Initial_magnetization_curve!Q17)*100 | F14: =AVERAGE(Initial_magnetization_curve!A58,Initial_magnetization_curve!D58,Initial_magnetization_curve!G58,Initial_magnetization_curve!J58,Initial_magnetization_curve!M58,Initial_magnetization_curve!P58) | G14: =STDEV(Initial_magnetization_curve!E58,Initial_magnetization_curve!N58)/AVERAGE(Initial_magnetization_curve!E58,Initial_magnetization_curve!N58)*100 | H14: =AVERAGE(Initial_magnetization_curve!A99,Initial_magnetization_curve!D99,Initial_magnetization_curve!G99,Initial_magnetization_curve!J99,Initial_magnetization_curve!M99,Initial_magnetization_curve!P99) | I14: =STDEV(Initial_magnetization_curve!E99,Initial_magnetization_curve!N99)/AVERAGE(Initial_magnetization_curve!E99,Initial_magnetization_curve!N99)*100 | J14: =AVERAGE(Initial_magnetization_curve!D17,Initial_magnetization_curve!G17,Initial_magnetization_curve!J17,Initial_magnetization_curve!M17,Initial_magnetization_curve!P17,A14,Initial_magnetization_curve!D58,Initial_magnetization_curve!M58,Initial_magnetization_curve!D99,Initial_magnetization_curve!M99) | K14: =STDEV(Initial_magnetization_curve!B17,Initial_magnetization_curve!E17,Initial_magnetization_curve!H17,Initial_magnetization_curve!K17,Initial_magnetization_curve!N17,Initial_magnetization_curve!Q17,Initial_magnetization_curve!E58,Initial_magnetization_curve!N58,Initial_magnetization_curve!E99,Initial_magnetization_curve!N99)/AVERAGE(Initial_magnetization_curve!B17,Initial_magnetization_curve!E17,Initial_magnetization_curve!H17,Initial_magnetization_curve!K17,Initial_magnetization_curve!N17,Initial_magnetization_curve!Q17,Initial_magnetization_curve!E58,Initial_magnetization_curve!N58,Initial_magnetization_curve!E99,Initial_magnetization_curve!N99)*100
... A38: =AVERAGE(Initial_magnetization_curve!A41,Initial_magnetization_curve!D41,Initial_magnetization_curve!G41,Initial_magnetization_curve!J41,Initial_magnetization_curve!M41,Initial_magnetization_curve!P41) | B38: =STDEV(Initial_magnetization_curve!B41,Initial_magnetization_curve!E41,Initial_magnetization_curve!H41)/AVERAGE(Initial_magnetization_curve!B41,Initial_magnetization_curve!E41,Initial_magnetization_curve!H41)*100 | C38: =STDEV(Initial_magnetization_curve!K41,Initial_magnetization_curve!N41,Initial_magnetization_curve!Q41)/AVERAGE(Initial_magnetization_curve!K41,Initial_magnetization_curve!N41,Initial_magnetization_curve!Q41)*100 | D38: =AVERAGE(Initial_magnetization_curve!D41,Initial_magnetization_curve!G41,Initial_magnetization_curve!J41,Initial_magnetization_curve!M41,Initial_magnetization_curve!P41,A38) | E38: =STDEV(Initial_magnetization_curve!B41,Initial_magnetization_curve!E41,Initial_magnetization_curve!H41,Initial_magnetization_curve!K41,Initial_magnetization_curve!N41,Initial_magnetization_curve!Q41)/AVERAGE(Initial_magnetization_curve!B41,Initial_magnetization_curve!E41,Initial_magnetization_curve!H41,Initial_magnetization_curve!K41,Initial_magnetization_curve!N41,Initial_magnetization_curve!Q41)*100 | F38: =AVERAGE(Initial_magnetization_curve!A82,Initial_magnetization_curve!D82,Initial_magnetization_curve!G82,Initial_magnetization_curve!J82,Initial_magnetization_curve!M82,Initial_magnetization_curve!P82) | G38: =STDEV(Initial_magnetization_curve!E82,Initial_magnetization_curve!N82)/AVERAGE(Initial_magnetization_curve!E82,Initial_magnetization_curve!N82)*100 | H38: =AVERAGE(Initial_magnetization_curve!A123,Initial_magnetization_curve!D123,Initial_magnetization_curve!G123,Initial_magnetization_curve!J123,Initial_magnetization_curve!M123,Initial_magnetization_curve!P123) | I38: =STDEV(Initial_magnetization_curve!E123,Initial_magnetization_curve!N123)/AVERAGE(Initial_magnetization_curve!E123,Initial_magnetization_curve!N123)*100 | J38: =AVERAGE(Initial_magnetization_curve!D41,Initial_magnetization_curve!G41,Initial_magnetization_curve!J41,Initial_magnetization_curve!M41,Initial_magnetization_curve!P41,A38,Initial_magnetization_curve!D82,Initial_magnetization_curve!M82,Initial_magnetization_curve!D123,Initial_magnetization_curve!M123) | K38: =STDEV(Initial_magnetization_curve!B41,Initial_magnetization_curve!E41,Initial_magnetization_curve!H41,Initial_magnetization_curve!K41,Initial_magnetization_curve!N41,Initial_magnetization_curve!Q41,Initial_magnetization_curve!E82,Initial_magnetization_curve!N82,Initial_magnetization_curve!E123,Initial_magnetization_curve!N123)/AVERAGE(Initial_magnetization_curve!B41,Initial_magnetization_curve!E41,Initial_magnetization_curve!H41,Initial_magnetization_curve!K41,Initial_magnetization_curve!N41,Initial_magnetization_curve!Q41,Initial_magnetization_curve!E82,Initial_magnetization_curve!N82,Initial_magnetization_curve!E123,Initial_magnetization_curve!N123)*100
